Workbook

Sheet 198
A1: ID | B1: Start time | C1: Completion time | D1: Email | E1: Name | F1: Last modified time | G1: Student Roll Number | H1: Student Name | I1: Department | J1: Select Category (Interested in Placement- Choose CRT otherwise Choose Non-CRT) | K1: Are you a Day Scholar or Hosteller student? | L1: Are you willing to Register for the courses offered during summer term (June 2026) in Acceleration mode? (Classwork Start Date: 25th May 2026) | M1: cse-3 | N1: counsellor | O1: Backlogs count | P1: Backlog courses | Q1: Specialization | R1: Acceleration | S1: 2-2 semester registered course | T1: 2-2 course name | U1: acceleration choice1 | V1: acceleration1 course code | W1: acceleration2 choice | X1: acceleration2course code | Y1: acceleration choice3 | Z1: acceleration choice3 | AA1: acceleration4 choice | AB1: course code
A2: 1 | B2: 46146.645 | C2: 46146.646 | D2: 2400030812@kluniversity.in | E2: OBULAPURAM VENNELA NAIDU OBULAPURAM VENNELA NAIDU | G2: 2400030812 | H2: Obulapuram Vennela Naidu | I2: CSE-3 | J2: Non-CRT | K2: Day Scholar | L2: Yes | M2: 8.28 | N2: Ch Phanikanth | O2: 0 | P2: 0 | Q2: DATA SCIENCE AND BIG DATA ANALYTICS | R2: Eligible for Acceleration | S2: =VLOOKUP(G2,[1]fc!$B$2:$D$707,3,0) -> 24CS2255F | T2: =VLOOKUP(G2,[1]fc!$B$2:$F$707,5,0) -> ADVANCED DATA STRUCTURES | U2: 24CS2237F | V2: QUANTUM COMPUTING | W2: 24CS2255F | X2: ADVANCED DATA STRUCTURES | Y2: 24CS2263F | Z2: CYBER THREAT INTELLIGENCE | AA2: 24CS2224F | AB2: CRYPT ANALYSIS AND CYBER DEFENCE
A3: 2 | B3: 46146.954 | C3: 46146.955 | D3: 2400031751@kluniversity.in | E3: RENUKA RAMKRISHNA RAYA RENUKA RAMKRISHNA RAYA | G3: 2400031751 | H3: Renuka Raya | I3: CSE-3 | J3: CRT (Campus Recruitment Training) | K3: Hostller | L3: Yes | M3: 8.79 | N3: Ch Phanikanth | O3: 0 | P3: 0 | Q3: AI-DRIVEN LANGUAGE TECHNOLOGIES | R3: Eligible for Acceleration | S3: =VLOOKUP(G3,[1]fc!$B$2:$D$707,3,0) -> 24CS2258F | T3: =VLOOKUP(G3,[1]fc!$B$2:$F$707,5,0) -> NATURAL LANGUAGE PROCESSING | U3: 24CS2237F | V3: QUANTUM COMPUTING | W3: 24CS2255F | X3: ADVANCED DATA STRUCTURES | Y3: 24CS2227F | Z3: DATA ANALYTICS AND VISUALIZATION | AA3: 24CS2263F | AB3: CYBER THREAT INTELLIGENCE
A4: 3 | B4: 46177.482 | C4: 46177.484 | D4: 2400030587@kluniversity.in | E4: BANDLA BHARGAVI BANDLA BHARGAVI | G4: 2400030587 | H4: Bandla Bhargavi | I4: CSE-3 | J4: CRT (Campus Recruitment Training) | K4: Day Scholar | L4: Yes | M4: 8.75 | N4: Ch Phanikanth | O4: 0 | P4: 0 | Q4: CYBER SECURITY AND BLOCKCHAIN TECHNOLOGY | R4: Eligible for Acceleration | S4: =VLOOKUP(G4,[1]fc!$B$2:$D$707,3,0) -> 24CS2255F | T4: =VLOOKUP(G4,[1]fc!$B$2:$F$707,5,0) -> ADVANCED DATA STRUCTURES | U4: 24CS2237F | V4: QUANTUM COMPUTING | W4: 24CS2255F | X4: ADVANCED DATA STRUCTURES | Y4: 24CS2227F | Z4: DATA ANALYTICS AND VISUALIZATION
A5: 4 | B5: 46177.953 | C5: 46177.955 | D5: 2400032124@kluniversity.in | E5: VEGESNA UMA NAGA SAI VARSHINI VARMA VEGESNA UMA NAGA SAI VARSHINI VARMA | G5: 2400032124 | H5: V.U.N.S.Varshini | I5: CSE-3 | J5: CRT (Campus Recruitment Training) | K5: Hostller | L5: Yes | M5: 9.1 | N5: Ch Phanikanth | O5: 0 | P5: 0 | Q5: AI-DRIVEN LANGUAGE TECHNOLOGIES | R5: Eligible for Acceleration | S5: =VLOOKUP(G5,[1]fc!$B$2:$D$707,3,0) -> 24CS2258F | T5: =VLOOKUP(G5,[1]fc!$B$2:$F$707,5,0) -> NATURAL LANGUAGE PROCESSING | U5: 24CS2237F | V5: QUANTUM COMPUTING | W5: 24CS2255F | X5: ADVANCED DATA STRUCTURES | Y5: 24CS2227F | Z5: DATA ANALYTICS AND VISUALIZATION | AA5: 24CS2263F | AB5: CYBER THREAT INTELLIGENCE
A6: 5 | B6: 46207.021 | C6: 46207.024 | D6: 2400031823@kluniversity.in | E6: BATNA VISHALI BATNA VISHALI | G6: 2400031823 | H6: Batna Vishali | I6: CSE-3 | J6: CRT (Campus Recruitment Training) | K6: Hostller | L6: Yes | M6: 8.8 | N6: Ch Phanikanth | O6: 0 | P6: 0 | Q6: AI-DRIVEN LANGUAGE TECHNOLOGIES | R6: Eligible for Acceleration | S6: =VLOOKUP(G6,[1]fc!$B$2:$D$707,3,0) -> 24CS2255F | T6: =VLOOKUP(G6,[1]fc!$B$2:$F$707,5,0) -> ADVANCED DATA STRUCTURES | U6: 24CS2237F | V6: QUANTUM COMPUTING | W6: 24CS2255F | X6: ADVANCED DATA STRUCTURES | Y6: 24CS2227F | Z6: DATA ANALYTICS AND VISUALIZATION | AA6: 24CS2263F | AB6: CYBER THREAT INTELLIGENCE
A7: 6 | B7: 46207.863 | C7: 46207.864 | D7: 2400030776@kluniversity.in | E7: CHERUKURI KUSMITHA CHERUKURI KUSMITHA | G7: 2400030776 | H7: Ch.Kusmitha | I7: CSE-3 | J7: CRT (Campus Recruitment Training) | K7: Day Scholar | L7: Yes | M7: 9.06 | N7: Ch Phanikanth | O7: 0 | P7: 0 | Q7: AI FOR COMPUTATIONAL INTELLIGENCE | R7: Eligible for Acceleration | S7: =VLOOKUP(G7,[1]fc!$B$2:$D$707,3,0) -> 24CS2224F | T7: =VLOOKUP(G7,[1]fc!$B$2:$F$707,5,0) -> CRYPT ANALYSIS AND CYBER DEFENCE | U7: 24CS2237F | V7: QUANTUM COMPUTING | W7: 24CS2255F | X7: ADVANCED DATA STRUCTURES | Y7: 24CS2227F | Z7: DATA ANALYTICS AND VISUALIZATION | AA7: 24CS2263F | AB7: CYBER THREAT INTELLIGENCE
A8: 7 | B8: 46146.895 | C8: 46146.896 | D8: 2400030925@kluniversity.in | E8: CHITHALURI VEERA HEMANTH CHITHALURI VEERA HEMANTH | G8: 2400030925 | H8: Ch veerahemanth | I8: CSE-3 | J8: CRT (Campus Recruitment Training) | K8: Hostller | L8: Yes | M8: 9.35 | N8: Dr. A Senthil (Hod) (Admin) | O8: 0 | P8: 0 | Q8: AI FOR COMPUTATIONAL INTELLIGENCE | R8: Eligible for Acceleration | S8: =VLOOKUP(G8,[1]fc!$B$2:$D$707,3,0) -> 24CS2224F | T8: =VLOOKUP(G8,[1]fc!$B$2:$F$707,5,0) -> CRYPT ANALYSIS AND CYBER DEFENCE | U8: 24CS2237F | V8: QUANTUM COMPUTING | W8: 24CS2255F | X8: ADVANCED DATA STRUCTURES | Y8: 24CS2227F | Z8: DATA ANALYTICS AND VISUALIZATION | AA8: 24CS2263F | AB8: CYBER THREAT INTELLIGENCE
A9: 8 | B9: 46177.49 | C9: 46177.491 | D9: 2400030274@kluniversity.in | E9: SHAIK TANVEER BASHA SHAIK TANVEER BASHA | G9: 2400030274 | H9: Shaik Tanveer Basha | I9: CSE-3 | J9: CRT (Campus Recruitment Training) | K9: Hostller | L9: Yes | M9: 9.47 | N9: Dr. A Senthil (Hod) (Admin) | O9: 0 | P9: 0 | Q9: AI FOR COMPUTATIONAL INTELLIGENCE | R9: Eligible for Acceleration | S9: =VLOOKUP(G9,[1]fc!$B$2:$D$707,3,0) -> 24CS2264F | T9: =VLOOKUP(G9,[1]fc!$B$2:$F$707,5,0) -> GAME SYSTEMS DESIGN AND DEVELOPMENT | U9: 24CS2237F | V9: QUANTUM COMPUTING | W9: 24CS2255F | X9: ADVANCED DATA STRUCTURES | Y9: 24CS2227F | Z9: DATA ANALYTICS AND VISUALIZATION | AA9: 24CS2263F | AB9: CYBER THREAT INTELLIGENCE
A10: 9 | B10: 46146.386 | C10: 46146.389 | D10: 2400030324@kluniversity.in | E10: GOKEDA MANIKANTA SAI GOKEDA MANIKANTA SAI | G10: 2400030324 | H10: GOKEDA MANIKANTA SAI | I10: CSE-3 | J10: CRT (Campus Recruitment Training) | K10: Day Scholar | L10: Yes | M10: 9.18 | N10: Dr. Mukkapati Naveen | O10: 0 | P10: 0 | Q10: AI FOR COMPUTATIONAL INTELLIGENCE | R10: Eligible for Acceleration | S10: =VLOOKUP(G10,[1]fc!$B$2:$D$707,3,0) -> 24CS2260F | T10: =VLOOKUP(G10,[1]fc!$B$2:$F$707,5,0) -> FOUNDATIONS OF CLOUD-NATIVE COMPUTING & DEVOPS | U10: 24CS2237F | V10: QUANTUM COMPUTING | W10: 24CS2255F | X10: ADVANCED DATA STRUCTURES | Y10: 24CS2227F | Z10: DATA ANALYTICS AND VISUALIZATION | AA10: 24CS2263F | AB10: CYBER THREAT INTELLIGENCE
A11: 10 | B11: 46146.886 | C11: 46146.888 | D11: 2400030312@kluniversity.in | E11: CHILUKURI AKASH SATYA VENKATA CHOWDARY CHILUKURI AKASH SATYA VENKATA CHOWDARY | G11: 2400030312 | H11: CHILUKURI AKASH SATYA VENKATA CHOWDARY | I11: CSE-3 | J11: CRT (Campus Recruitment Training) | K11: Hostller | L11: Yes | M11: 8.31 | N11: Dr. Mukkapati Naveen | O11: 0 | P11: 0 | Q11: AI FOR COMPUTATIONAL INTELLIGENCE | R11: Eligible for Acceleration | S11: =VLOOKUP(G11,[1]fc!$B$2:$D$707,3,0) -> 24CS2237F | T11: =VLOOKUP(G11,[1]fc!$B$2:$F$707,5,0) -> QUANTUM COMPUTING | U11: 24CS2237F | V11: QUANTUM COMPUTING | W11: 24CS2255F | X11: ADVANCED DATA STRUCTURES | Y11: 24CS2227F | Z11: DATA ANALYTICS AND VISUALIZATION | AA11: 24CS2263F | AB11: CYBER THREAT INTELLIGENCE
A12: 11 | B12: 46177.447 | C12: 46177.449 | D12: 2400031003@kluniversity.in | E12: JAKKAMPUDI AVINASH CHOWDARY JAKKAMPUDI AVINASH CHOWDARY | G12: 2400031003 | H12: JAKKAMPUDI AVINASH CHOWDARY | I12: CSE-3 | J12: CRT (Campus Recruitment Training) | K12: Day Scholar | L12: Yes | M12: 9.02 | N12: Dr. Mukkapati Naveen | O12: 0 | P12: 0 | Q12: CYBER SECURITY AND BLOCKCHAIN TECHNOLOGY | R12: Eligible for Acceleration | S12: =VLOOKUP(G12,[1]fc!$B$2:$D$707,3,0) -> 24CS2239F | T12: =VLOOKUP(G12,[1]fc!$B$2:$F$707,5,0) -> SOFTWARE VERIFICATION AND VALIDATION | U12: 24CS2237F | V12: QUANTUM COMPUTING | W12: 24CS2255F | X12: ADVANCED DATA STRUCTURES | Y12: 24CS2227F | Z12: DATA ANALYTICS AND VISUALIZATION
A13: 12 | B13: 46177.692 | C13: 46177.692 | D13: 2400030875@kluniversity.in | E13: PENUMUCHU DEVENDRANADH PENUMUCHU DEVENDRANADH | G13: 2400030875 | H13: Devendranadh | I13: CSE-3 | J13: CRT (Campus Recruitment Training) | K13: Day Scholar | L13: Yes | M13: 8.45 | N13: Dr. Mukkapati Naveen | O13: 0 | P13: 0 | Q13: AI SYSTEMS FOR VISUAL INTELLIGENCE | R13: Eligible for Acceleration | S13: =VLOOKUP(G13,[1]fc!$B$2:$D$707,3,0) -> 24CS2221F | T13: =VLOOKUP(G13,[1]fc!$B$2:$F$707,5,0) -> UX DESIGN | U13: 24CS2237F | V13: QUANTUM COMPUTING | W13: 24CS2255F | X13: ADVANCED DATA STRUCTURES | Y13: 24CS2227F | Z13: DATA ANALYTICS AND VISUALIZATION | AA13: 24CS2263F | AB13: CYBER THREAT INTELLIGENCE
A14: 13 | B14: 46207.907 | C14: 46207.909 | D14: 2400030942@kluniversity.in | E14: SANDA SRINATH SANDA SRINATH | G14: 2400030942 | H14: Sanda Srinath | I14: CSE-3 | J14: CRT (Campus Recruitment Training) | K14: Hostller | L14: Yes | M14: 9.18 | N14: Dr. Mukkapati Naveen | O14: 0 | P14: 0 | Q14: AI SYSTEMS FOR VISUAL INTELLIGENCE | R14: Eligible for Acceleration | S14: =VLOOKUP(G14,[1]fc!$B$2:$D$707,3,0) -> 24CS2221F | T14: =VLOOKUP(G14,[1]fc!$B$2:$F$707,5,0) -> UX DESIGN | U14: 24CS2237F | V14: QUANTUM COMPUTING | W14: 24CS2255F | X14: ADVANCED DATA STRUCTURES | Y14: 24CS2227F | Z14: DATA ANALYTICS AND VISUALIZATION | AA14: 24CS2263F | AB14: CYBER THREAT INTELLIGENCE
A15: 14 | B15: 46146.382 | C15: 46146.384 | D15: 2400030563@kluniversity.in | E15: THAMMISETTY MAHESH BABU THAMMISETTY MAHESH BABU | G15: 2400030563 | H15: T.MAHESH BABU | I15: CSE-3 | J15: CRT (Campus Recruitment Training) | K15: Day Scholar | L15: Yes | M15: 8 | N15: Dr. P. V. Venkateswara Rao | O15: 0 | P15: 0 | Q15: AI FOR COMPUTATIONAL INTELLIGENCE | R15: Eligible for Acceleration | S15: =VLOOKUP(G15,[1]fc!$B$2:$D$707,3,0) -> 24CS2255F | T15: =VLOOKUP(G15,[1]fc!$B$2:$F$707,5,0) -> ADVANCED DATA STRUCTURES | U15: 24CS2237F | V15: QUANTUM COMPUTING | W15: 24CS2255F | X15: ADVANCED DATA STRUCTURES | Y15: 24CS2227F | Z15: DATA ANALYTICS AND VISUALIZATION | AA15: 24CS2263F | AB15: CYBER THREAT INTELLIGENCE
A16: 15 | B16: 46146.492 | C16: 46146.492 | D16: 2400032261@kluniversity.in | E16: MANNEM SASI VEDHAVATHI MANNEM SASI VEDHAVATHI | G16: 2400032261 | H16: Mannem Sasi Vedhavathi | I16: CSE-3 | J16: CRT (Campus Recruitment Training) | K16: Hostller | L16: Yes | M16: 9.18 | N16: Dr. Prerna Mohit | O16: 0 | P16: 0 | Q16: AI-DRIVEN LANGUAGE TECHNOLOGIES | R16: Eligible for Acceleration | S16: =VLOOKUP(G16,[1]fc!$B$2:$D$707,3,0) -> 24CS2260F | T16: =VLOOKUP(G16,[1]fc!$B$2:$F$707,5,0) -> FOUNDATIONS OF CLOUD-NATIVE COMPUTING & DEVOPS | U16: 24CS2237F | V16: QUANTUM COMPUTING | W16: 24CS2255F | X16: ADVANCED DATA STRUCTURES | Y16: 24CS2227F | Z16: DATA ANALYTICS AND VISUALIZATION
A17: 16 | B17: 46146.891 | C17: 46146.891 | D17: 2400031008@kluniversity.in | E17: MADDUKURI VIDYA NANDH MADDUKURI VIDYA NANDH | G17: 2400031008 | H17: M vidya nandh | I17: CSE-3 | J17: CRT (Campus Recruitment Training) | K17: Hostller | L17: Yes | M17: 8.02 | N17: Dr. P. V. Venkateswara Rao | O17: 0 | P17: 0 | Q17: DATA ENGINEERING FOR AI | R17: Eligible for Acceleration | S17: =VLOOKUP(G17,[1]fc!$B$2:$D$707,3,0) -> 24CS2258F | T17: =VLOOKUP(G17,[1]fc!$B$2:$F$707,5,0) -> NATURAL LANGUAGE PROCESSING | U17: 24CS2237F | V17: QUANTUM COMPUTING | W17: 24CS2255F | X17: ADVANCED DATA STRUCTURES | Y17: 24CS2263F | Z17: CYBER THREAT INTELLIGENCE | AA17: 24CS2224F | AB17: CRYPT ANALYSIS AND CYBER DEFENCE
A18: 17 | B18: 46146.945 | C18: 46146.945 | D18: 2400030866@kluniversity.in | E18: GAJJELA HARI MANIKANTA REDDY GAJJELA HARI MANIKANTA REDDY | G18: 2400030866 | H18: G. Hari ManiKanta Reddy | I18: CSE-3 | J18: CRT (Campus Recruitment Training) | K18: Day Scholar | L18: Yes | M18: 8.39 | N18: Dr. P. V. Venkateswara Rao | O18: 0 | P18: 0 | Q18: AI SYSTEMS FOR VISUAL INTELLIGENCE | R18: Eligible for Acceleration | S18: =VLOOKUP(G18,[1]fc!$B$2:$D$707,3,0) -> 24CS2227F | T18: =VLOOKUP(G18,[1]fc!$B$2:$F$707,5,0) -> DATA ANALYTICS AND VISUALIZATION | U18: 24CS2237F | V18: QUANTUM COMPUTING | W18: 24CS2255F | X18: ADVANCED DATA STRUCTURES | Y18: 24CS2227F | Z18: DATA ANALYTICS AND VISUALIZATION | AA18: 24CS2263F | AB18: CYBER THREAT INTELLIGENCE
A19: 18 | B19: 46177.316 | C19: 46177.317 | D19: 2400031636@kluniversity.in | E19: VEPURI ARUN KUMAR VEPURI ARUN KUMAR | G19: 2400031636 | H19: V. ARUN KUMAR | I19: CSE-3 | J19: CRT (Campus Recruitment Training) | K19: Day Scholar | L19: Yes | M19: 8.84 | N19: Dr. P. V. Venkateswara Rao | O19: 0 | P19: 0 | Q19: DATA SCIENCE AND BIG DATA ANALYTICS | R19: Eligible for Acceleration | S19: =VLOOKUP(G19,[1]fc!$B$2:$D$707,3,0) -> 24CS2258F | T19: =VLOOKUP(G19,[1]fc!$B$2:$F$707,5,0) -> NATURAL LANGUAGE PROCESSING | U19: 24CS2237F | V19: QUANTUM COMPUTING | W19: 24CS2255F | X19: ADVANCED DATA STRUCTURES | Y19: 24CS2263F | Z19: CYBER THREAT INTELLIGENCE | AA19: 24CS2224F | AB19: CRYPT ANALYSIS AND CYBER DEFENCE
A20: 19 | B20: 46177.766 | C20: 46177.766 | D20: 2400031312@kluniversity.in | E20: DANNANA DURGA PRASAD DANNANA DURGA PRASAD | G20: 2400031312 | H20: Dannana durga prasad | I20: CSE-3 | J20: CRT (Campus Recruitment Training) | K20: Day Scholar | L20: Yes | M20: 8.56 | N20: Dr. P. V. Venkateswara Rao | O20: 0 | P20: 0 | Q20: AI AND AUTONOMOUS SYSTEMS | R20: Eligible for Acceleration | S20: =VLOOKUP(G20,[1]fc!$B$2:$D$707,3,0) -> 24EE2230F | T20: =VLOOKUP(G20,[1]fc!$B$2:$F$707,5,0) -> ESSENTIALS OF AUTONOMOUS SYSTEMS | U20: 24CS2237F | V20: QUANTUM COMPUTING | W20: 24CS2255F | X20: ADVANCED DATA STRUCTURES | Y20: 24CS2227F | Z20: DATA ANALYTICS AND VISUALIZATION | AA20: 24CS2263F | AB20: CYBER THREAT INTELLIGENCE
A21: 20 | B21: 46207.469 | C21: 46207.47 | D21: 2400030986@kluniversity.in | E21: PETETI ABHILASH PETETI ABHILASH | G21: 2400030986 | H21: PETETI ABHILASH | I21: CSE-3 | J21: CRT (Campus Recruitment Training) | K21: Day Scholar | L21: Yes | M21: 8.19 | N21: Dr. P. V. Venkateswara Rao | O21: 0 | P21: 0 | Q21: AI SYSTEMS FOR VISUAL INTELLIGENCE | R21: Eligible for Acceleration | S21: =VLOOKUP(G21,[1]fc!$B$2:$D$707,3,0) -> 24CS2255F | T21: =VLOOKUP(G21,[1]fc!$B$2:$F$707,5,0) -> ADVANCED DATA STRUCTURES | U21: 24CS2237F | V21: QUANTUM COMPUTING | W21: 24CS2255F | X21: ADVANCED DATA STRUCTURES | Y21: 24CS2227F | Z21: DATA ANALYTICS AND VISUALIZATION | AA21: 24CS2263F | AB21: CYBER THREAT INTELLIGENCE
A22: 21 | B22: 46116.949 | C22: 46116.95 | D22: 2400030264@kluniversity.in | E22: ATTULURI LALITHA SIVA PRIYA ATTULURI LALITHA SIVA PRIYA | G22: 2400030264 | H22: A.Lalitha siva priya | I22: CSE-3 | J22: CRT (Campus Recruitment Training) | K22: Day Scholar | L22: Yes | M22: 8.91 | N22: Dr. Prerna Mohit | O22: 0 | P22: 0 | Q22: AI FOR COMPUTATIONAL INTELLIGENCE | R22: Eligible for Acceleration | S22: =VLOOKUP(G22,[1]fc!$B$2:$D$707,3,0) -> 24CS2255F | T22: =VLOOKUP(G22,[1]fc!$B$2:$F$707,5,0) -> ADVANCED DATA STRUCTURES | U22: 24CS2237F | V22: QUANTUM COMPUTING | W22: 24CS2255F | X22: ADVANCED DATA STRUCTURES | Y22: 24CS2227F | Z22: DATA ANALYTICS AND VISUALIZATION | AA22: 24CS2263F | AB22: CYBER THREAT INTELLIGENCE
A23: 22 | B23: 46146.985 | C23: 46146.985 | D23: 2400032478@kluniversity.in | E23: LANKALAPALLI SURYA TEJA LANKALAPALLI SURYA TEJA | G23: 2400032478 | H23: L surya teja | I23: CSE-3 | J23: CRT (Campus Recruitment Training) | K23: Day Scholar | L23: Yes | M23: 8.54 | N23: Dr. Prerna Mohit | O23: 0 | P23: 0 | Q23: AI-DRIVEN LANGUAGE TECHNOLOGIES | R23: Eligible for Acceleration | S23: =VLOOKUP(G23,[1]fc!$B$2:$D$707,3,0) -> 24CS2255F | T23: =VLOOKUP(G23,[1]fc!$B$2:$F$707,5,0) -> ADVANCED DATA STRUCTURES | U23: 24CS2237F | V23: QUANTUM COMPUTING | W23: 24CS2255F | X23: ADVANCED DATA STRUCTURES | Y23: 24CS2227F | Z23: DATA ANALYTICS AND VISUALIZATION | AA23: 24CS2263F | AB23: CYBER THREAT INTELLIGENCE
A24: 23 | B24: 46146.519 | C24: 46146.521 | D24: 2400032360@kluniversity.in | E24: KHAMMAMPATI SAI SRUTHIKA KHAMMAMPATI SAI SRUTHIKA | G24: 2400032360 | H24: Khammampati Sai Sruthika | I24: CSE-3 | J24: CRT (Campus Recruitment Training) | K24: Hostller | L24: Yes | M24: 9.14 | N24: Dr. Prerna Mohit | O24: 0 | P24: 0 | Q24: AI FOR COMPUTATIONAL INTELLIGENCE | R24: Eligible for Acceleration | S24: =VLOOKUP(G24,[1]fc!$B$2:$D$707,3,0) -> 24CS2237F | T24: =VLOOKUP(G24,[1]fc!$B$2:$F$707,5,0) -> QUANTUM COMPUTING | U24: 24CS2237F | V24: QUANTUM COMPUTING | W24: 24CS2255F | X24: ADVANCED DATA STRUCTURES | Y24: 24CS2227F | Z24: DATA ANALYTICS AND VISUALIZATION | AA24: 24CS2263F | AB24: CYBER THREAT INTELLIGENCE
A25: 24 | B25: 46146.973 | C25: 46146.975 | D25: 2400030588@kluniversity.in | E25: MURIKIPUDI ANANYA MURIKIPUDI ANANYA | G25: 2400030588 | H25: M. Ananya | I25: CSE-3 | J25: CRT (Campus Recruitment Training) | K25: Day Scholar | L25: Yes | M25: 8.85 | N25: Dr. Prerna Mohit | O25: 0 | P25: 0 | Q25: AI FOR COMPUTATIONAL INTELLIGENCE | R25: Eligible for Acceleration | S25: =VLOOKUP(G25,[1]fc!$B$2:$D$707,3,0) -> 24CS2258F | T25: =VLOOKUP(G25,[1]fc!$B$2:$F$707,5,0) -> NATURAL LANGUAGE PROCESSING | U25: 24CS2237F | V25: QUANTUM COMPUTING | W25: 24CS2255F | X25: ADVANCED DATA STRUCTURES | Y25: 24CS2227F | Z25: DATA ANALYTICS AND VISUALIZATION | AA25: 24CS2263F | AB25: CYBER THREAT INTELLIGENCE
A26: 25 | B26: 46177.601 | C26: 46177.602 | D26: 2400032362@kluniversity.in | E26: PANDILLAPALLI YASASWINI PANDILLAPALLI YASASWINI | G26: 2400032362 | H26: P Yasaswini | I26: CSE-3 | J26: CRT (Campus Recruitment Training) | K26: Hostller | L26: Yes | M26: 8.68 | N26: Dr. Prerna Mohit | O26: 0 | P26: 0 | Q26: AI-DRIVEN LANGUAGE TECHNOLOGIES | R26: Eligible for Acceleration | S26: =VLOOKUP(G26,[1]fc!$B$2:$D$707,3,0) -> 24CS2227F | T26: =VLOOKUP(G26,[1]fc!$B$2:$F$707,5,0) -> DATA ANALYTICS AND VISUALIZATION | U26: 24CS2237F | V26: QUANTUM COMPUTING | W26: 24CS2255F | X26: ADVANCED DATA STRUCTURES | Y26: 24CS2227F | Z26: DATA ANALYTICS AND VISUALIZATION | AA26: 24CS2263F | AB26: CYBER THREAT INTELLIGENCE
A27: 26 | B27: 46177.101 | C27: 46177.102 | D27: 2400031513@kluniversity.in | E27: PONNURU YOSHITHA PONNURU YOSHITHA | G27: 2400031513 | H27: Yoshitha.p | I27: CSE-3 | J27: CRT (Campus Recruitment Training) | K27: Day Scholar | L27: Yes | M27: 8.4 | N27: Dr. Prerna Mohit | O27: 0 | P27: 0 | Q27: DATA SCIENCE AND BIG DATA ANALYTICS | R27: Eligible for Acceleration | S27: =VLOOKUP(G27,[1]fc!$B$2:$D$707,3,0) -> 24CS2255F | T27: =VLOOKUP(G27,[1]fc!$B$2:$F$707,5,0) -> ADVANCED DATA STRUCTURES | U27: 24CS2237F | V27: QUANTUM COMPUTING | W27: 24CS2255F | X27: ADVANCED DATA STRUCTURES | Y27: 24CS2263F | Z27: CYBER THREAT INTELLIGENCE | AA27: 24CS2224F | AB27: CRYPT ANALYSIS AND CYBER DEFENCE
A28: 27 | B28: 46177.563 | C28: 46177.566 | D28: 2400030260@kluniversity.in | E28: DEVARASETTY DIVYA TEJASWINI DEVARASETTY DIVYA TEJASWINI | G28: 2400030260 | H28: D.Divya Tejaswini | I28: CSE-3 | J28: CRT (Campus Recruitment Training) | K28: Day Scholar | L28: Yes | M28: 9.13 | N28: Dr. Prerna Mohit | O28: 0 | P28: 0 | Q28: AI FOR COMPUTATIONAL INTELLIGENCE | R28: Eligible for Acceleration | S28: =VLOOKUP(G28,[1]fc!$B$2:$D$707,3,0) -> 24CS2227F | T28: =VLOOKUP(G28,[1]fc!$B$2:$F$707,5,0) -> DATA ANALYTICS AND VISUALIZATION | U28: 24CS2237F | V28: QUANTUM COMPUTING | W28: 24CS2255F | X28: ADVANCED DATA STRUCTURES | Y28: 24CS2227F | Z28: DATA ANALYTICS AND VISUALIZATION | AA28: 24CS2263F | AB28: CYBER THREAT INTELLIGENCE
A29: 28 | B29: 46146.426 | C29: 46146.427 | D29: 2400031255@kluniversity.in | E29: MOTHUKURI NIKHIL KARTHIK MOTHUKURI NIKHIL KARTHIK | G29: 2400031255 | H29: M.NIKHIL KARTHIK | I29: CSE-3 | J29: CRT (Campus Recruitment Training) | K29: Day Scholar | L29: Yes | M29: 8.17 | N29: Dr. Saiyed Faiayaz Waris | O29: 0 | P29: 0 | Q29: AI-DRIVEN LANGUAGE TECHNOLOGIES | R29: Eligible for Acceleration | S29: =VLOOKUP(G29,[1]fc!$B$2:$D$707,3,0) -> 24CS2221F | T29: =VLOOKUP(G29,[1]fc!$B$2:$F$707,5,0) -> UX DESIGN | U29: 24CS2237F | V29: QUANTUM COMPUTING | W29: 24CS2255F | X29: ADVANCED DATA STRUCTURES | Y29: 24CS2227F | Z29: DATA ANALYTICS AND VISUALIZATION | AA29: 24CS2263F | AB29: CYBER THREAT INTELLIGENCE
A30: 29 | B30: 46177.655 | C30: 46177.655 | D30: 2400032443@kluniversity.in | E30: SIVAPURAM VEDA HASINI SIVAPURAM VEDA HASINI | G30: 2400032443 | H30: SIVAPURAM VEDA HASINI | I30: CSE-3 | J30: CRT (Campus Recruitment Training) | K30: Hostller | L30: Yes | M30: 8.94 | N30: Dr. Prerna Mohit | O30: 0 | P30: 0 | Q30: CYBER SECURITY AND BLOCKCHAIN TECHNOLOGY | R30: Eligible for Acceleration | S30: =VLOOKUP(G30,[1]fc!$B$2:$D$707,3,0) -> 24CS2256F | T30: =VLOOKUP(G30,[1]fc!$B$2:$F$707,5,0) -> FOUNDATIONS OF BLOCK CHAIN ENGINEERING | U30: 24CS2237F | V30: QUANTUM COMPUTING | W30: 24CS2255F | X30: ADVANCED DATA STRUCTURES | Y30: 24CS2227F | Z30: DATA ANALYTICS AND VISUALIZATION
A31: 30 | B31: 46177.665 | C31: 46177.666 | D31: 2400030940@kluniversity.in | E31: CHINTHALACHERUVU TEJASREE CHINTHALACHERUVU TEJASREE | G31: 2400030940 | H31: Ch.Teja sree | I31: CSE-3 | J31: CRT (Campus Recruitment Training) | K31: Day Scholar | L31: Yes | M31: 9.03 | N31: Dr. Prerna Mohit | O31: 0 | P31: 0 | Q31: CLOUD INFRASTRUCTURE DESIGN AND ENGINEERING | R31: Eligible for Acceleration | S31: =VLOOKUP(G31,[1]fc!$B$2:$D$707,3,0) -> 24CS2221F | T31: =VLOOKUP(G31,[1]fc!$B$2:$F$707,5,0) -> UX DESIGN | U31: 24CS2237F | V31: QUANTUM COMPUTING | W31: 24CS2255F | X31: ADVANCED DATA STRUCTURES | Y31: 24CS2227F | Z31: DATA ANALYTICS AND VISUALIZATION | AA31: 24CS2263F | AB31: CYBER THREAT INTELLIGENCE
A32: 31 | B32: 46146.442 | C32: 46146.447 | D32: 2400031531@kluniversity.in | E32: SALADI SATYA BHAVANI SHANKAR SALADI SATYA BHAVANI SHANKAR | G32: 2400031531 | H32: Saladi satya bhavani shankar | I32: CSE-3 | J32: CRT (Campus Recruitment Training) | K32: Hostller | L32: Yes | M32: 8.11 | N32: Dr. Saiyed Faiayaz Waris | O32: 0 | P32: 0 | Q32: AI-DRIVEN LANGUAGE TECHNOLOGIES | R32: Eligible for Acceleration | S32: =VLOOKUP(G32,[1]fc!$B$2:$D$707,3,0) -> 24CS2221F | T32: =VLOOKUP(G32,[1]fc!$B$2:$F$707,5,0) -> UX DESIGN | U32: 24CS2237F | V32: QUANTUM COMPUTING | W32: 24CS2255F | X32: ADVANCED DATA STRUCTURES | Y32: 24CS2227F | Z32: DATA ANALYTICS AND VISUALIZATION | AA32: 24CS2263F | AB32: CYBER THREAT INTELLIGENCE
A33: 32 | B33: 46146.443 | C33: 46146.444 | D33: 2400031685@kluniversity.in | E33: BANDARU NITYA SRI GOWRI BANDARU NITYA SRI GOWRI | G33: 2400031685 | H33: Bandaru Nitya Sri Gowri | I33: CSE-3 | J33: CRT (Campus Recruitment Training) | K33: Hostller | L33: Yes | M33: 8.45 | N33: Dr. Saziya Tabbasum | O33: 0 | P33: 0 | Q33: AI-DRIVEN LANGUAGE TECHNOLOGIES | R33: Eligible for Acceleration | S33: =VLOOKUP(G33,[1]fc!$B$2:$D$707,3,0) -> 24CS2239F | T33: =VLOOKUP(G33,[1]fc!$B$2:$F$707,5,0) -> SOFTWARE VERIFICATION AND VALIDATION | U33: 24CS2237F | V33: QUANTUM COMPUTING | W33: 24CS2255F | X33: ADVANCED DATA STRUCTURES | Y33: 24CS2227F | Z33: DATA ANALYTICS AND VISUALIZATION | AA33: 24CS2263F | AB33: CYBER THREAT INTELLIGENCE
A34: 33 | B34: 46177.385 | C34: 46177.385 | D34: 2400030695@kluniversity.in | E34: ALLURI HEMANTH CHOWDARY ALLURI HEMANTH CHOWDARY | G34: 2400030695 | H34: ALLURI HEMANTH CHOWDARY | I34: CSE-3 | J34: CRT (Campus Recruitment Training) | K34: Hostller | L34: Yes | M34: 8.64 | N34: Dr. Saiyed Faiayaz Waris | O34: 0 | P34: 0 | Q34: DATA ENGINEERING FOR AI | R34: Eligible for Acceleration | S34: =VLOOKUP(G34,[1]fc!$B$2:$D$707,3,0) -> 24CS2258F | T34: =VLOOKUP(G34,[1]fc!$B$2:$F$707,5,0) -> NATURAL LANGUAGE PROCESSING | U34: 24CS2237F | V34: QUANTUM COMPUTING | W34: 24CS2255F | X34: ADVANCED DATA STRUCTURES | Y34: 24CS2263F | Z34: CYBER THREAT INTELLIGENCE | AA34: 24CS2224F | AB34: CRYPT ANALYSIS AND CYBER DEFENCE
A35: 34 | B35: 46177.54 | C35: 46177.541 | D35: 2400031227@kluniversity.in | E35: NALLA ROHITH NALLA ROHITH | G35: 2400031227 | H35: Nalla Rohith | I35: CSE-3 | J35: CRT (Campus Recruitment Training) | K35: Day Scholar | L35: Yes | M35: 8.86 | N35: Dr. Saiyed Faiayaz Waris | O35: 0 | P35: 0 | Q35: AI SYSTEMS FOR VISUAL INTELLIGENCE | R35: Eligible for Acceleration | S35: =VLOOKUP(G35,[1]fc!$B$2:$D$707,3,0) -> 24CS2255F | T35: =VLOOKUP(G35,[1]fc!$B$2:$F$707,5,0) -> ADVANCED DATA STRUCTURES | U35: 24CS2237F | V35: QUANTUM COMPUTING | W35: 24CS2255F | X35: ADVANCED DATA STRUCTURES | Y35: 24CS2227F | Z35: DATA ANALYTICS AND VISUALIZATION | AA35: 24CS2263F | AB35: CYBER THREAT INTELLIGENCE
A36: 35 | B36: 46177.562 | C36: 46177.564 | D36: 2400032669@kluniversity.in | E36: KATRA GADDA DEVESH CHOWDARY KATRA GADDA DEVESH CHOWDARY | G36: 2400032669 | H36: K.Devesh chowdary | I36: CSE-3 | J36: CRT (Campus Recruitment Training) | K36: Day Scholar | L36: Yes | M36: 9.11 | N36: Dr. Saiyed Faiayaz Waris | O36: 0 | P36: 0 | Q36: AI SYSTEMS FOR VISUAL INTELLIGENCE | R36: Eligible for Acceleration | S36: =VLOOKUP(G36,[1]fc!$B$2:$D$707,3,0) -> 24CS2258F | T36: =VLOOKUP(G36,[1]fc!$B$2:$F$707,5,0) -> NATURAL LANGUAGE PROCESSING | U36: 24CS2237F | V36: QUANTUM COMPUTING | W36: 24CS2255F | X36: ADVANCED DATA STRUCTURES | Y36: 24CS2227F | Z36: DATA ANALYTICS AND VISUALIZATION | AA36: 24CS2263F | AB36: CYBER THREAT INTELLIGENCE
A37: 36 | B37: 46146.389 | C37: 46146.39 | D37: 2400031709@kluniversity.in | E37: INDURU JASWITHA INDURU JASWITHA | G37: 2400031709 | H37: INDURU JASWITHA | I37: CSE-3 | J37: CRT (Campus Recruitment Training) | K37: Hostller | L37: Yes | M37: 8.18 | N37: Dr. Saziya Tabbasum | O37: 0 | P37: 0 | Q37: AI AND AUTONOMOUS SYSTEMS | R37: Eligible for Acceleration | S37: =VLOOKUP(G37,[1]fc!$B$2:$D$707,3,0) -> 24EE2230F | T37: =VLOOKUP(G37,[1]fc!$B$2:$F$707,5,0) -> ESSENTIALS OF AUTONOMOUS SYSTEMS | U37: 24CS2237F | V37: QUANTUM COMPUTING | W37: 24CS2255F | X37: ADVANCED DATA STRUCTURES | Y37: 24CS2227F | Z37: DATA ANALYTICS AND VISUALIZATION | AA37: 24CS2263F | AB37: CYBER THREAT INTELLIGENCE
A38: 37 | B38: 46146.4 | C38: 46146.401 | D38: 2400030466@kluniversity.in | E38: KOMIRISETTY TANUJESWARI KOMIRISETTY TANUJESWARI | G38: 2400030466 | H38: KOMIRISETTY TANUJESWARI | I38: CSE-3 | J38: CRT (Campus Recruitment Training) | K38: Day Scholar | L38: Yes | M38: 8.88 | N38: Dr. Saziya Tabbasum | O38: 0 | P38: 0 | Q38: DATA ENGINEERING FOR AI | R38: Eligible for Acceleration | S38: =VLOOKUP(G38,[1]fc!$B$2:$D$707,3,0) -> 24CS2224F | T38: =VLOOKUP(G38,[1]fc!$B$2:$F$707,5,0) -> CRYPT ANALYSIS AND CYBER DEFENCE | U38: 24CS2237F | V38: QUANTUM COMPUTING | W38: 24CS2255F | X38: ADVANCED DATA STRUCTURES | Y38: 24CS2263F | Z38: CYBER THREAT INTELLIGENCE | AA38: 24CS2224F | AB38: CRYPT ANALYSIS AND CYBER DEFENCE
A39: 38 | B39: 46146.448 | C39: 46146.448 | D39: 2400031617@kluniversity.in | E39: BHARGHAVI M BHARGHAVI M | G39: 2400031617 | H39: Bharghavi M | I39: CSE-3 | J39: CRT (Campus Recruitment Training) | K39: Day Scholar | L39: Yes | M39: 8.85 | N39: Dr. Saziya Tabbasum | O39: 0 | P39: 0 | Q39: AI-DRIVEN LANGUAGE TECHNOLOGIES | R39: Eligible for Acceleration | S39: =VLOOKUP(G39,[1]fc!$B$2:$D$707,3,0) -> 24CS2260F | T39: =VLOOKUP(G39,[1]fc!$B$2:$F$707,5,0) -> FOUNDATIONS OF CLOUD-NATIVE COMPUTING & DEVOPS | U39: 24CS2237F | V39: QUANTUM COMPUTING | W39: 24CS2255F | X39: ADVANCED DATA STRUCTURES | Y39: 24CS2227F | Z39: DATA ANALYTICS AND VISUALIZATION | AA39: 24CS2263F | AB39: CYBER THREAT INTELLIGENCE
A40: 39 | B40: 46146.903 | C40: 46146.904 | D40: 2400030916@kluniversity.in | E40: PONUGOTI NIKHITHA REDDY PONUGOTI NIKHITHA REDDY | G40: 2400030916 | H40: P.Nikhitha Reddy | I40: CSE-3 | J40: CRT (Campus Recruitment Training) | K40: Day Scholar | L40: Yes | M40: 8.8 | N40: Dr. Saziya Tabbasum | O40: 0 | P40: 0 | Q40: AI-DRIVEN LANGUAGE TECHNOLOGIES | R40: Eligible for Acceleration | S40: =VLOOKUP(G40,[1]fc!$B$2:$D$707,3,0) -> 24CS2255F | T40: =VLOOKUP(G40,[1]fc!$B$2:$F$707,5,0) -> ADVANCED DATA STRUCTURES | U40: 24CS2237F | V40: QUANTUM COMPUTING | W40: 24CS2255F | X40: ADVANCED DATA STRUCTURES | Y40: 24CS2227F | Z40: DATA ANALYTICS AND VISUALIZATION | AA40: 24CS2263F | AB40: CYBER THREAT INTELLIGENCE
...

Sheet CHECK
A1: Department of CSE-3 - Acceleration Eligibile List
A2: 1 | B2: Student Roll Number | C2: <<Enter Your Roll Number>>
A3: 2 | B3: Student Name | C3: =VLOOKUP(C2,'198'!G2:H199,2,0) -> #N/A
A4: 3 | B4: Department | C4: =VLOOKUP(C2,'198'!G2:I199,3,0) -> #N/A
A5: 4 | B5: Select Category (Interested in Placement- Choose CRT otherwise Choose Non-CRT) | C5: =VLOOKUP(C2,'198'!G2:J199,4,0) -> #N/A
A6: 5 | B6: Are you a Day Scholar or Hosteller student? | C6: =VLOOKUP(C2,'198'!G2:K199,5,0) -> #N/A
A7: 6 | B7: counsellor | C7: =VLOOKUP(C2,'198'!G2:N199,8,0) -> #N/A
A8: 7 | B8: CGPA | C8: =VLOOKUP(C2,'198'!G2:M199,7,0) -> #N/A
A9: 8 | B9: Backlogs count | C9: =VLOOKUP(C2,'198'!G2:O199,9,0) -> #N/A
A10: 10 | B10: Specialization | C10: =VLOOKUP(C2,'198'!G2:Q199,11,0) -> #N/A
A11: 11 | B11: Acceleration | C11: =VLOOKUP(C2,'198'!G2:R199,12,0) -> #N/A
A12: 12 | B12: Previous semester 2-2 semester registered course | C12: =VLOOKUP(C2,'198'!G2:S199,13,0) -> #N/A
A13: 13 | B13: Previous semester 2-2 course name | C13: =VLOOKUP(C2,'198'!G2:T199,14,0) -> #N/A
A14: NOTE- Please check your previous semester Flexi Core registration and register for a different Flexi Core course as per the Flexi Core table.
